<?xml version="1.0" encoding="UTF-8"?>
<testng-results skipped="0" failed="1" total="1" passed="0">
  <reporter-output>
  </reporter-output>
  <suite name="Suite" duration-ms="68817" started-at="2019-03-28T13:53:07Z" finished-at="2019-03-28T13:54:16Z">
    <groups>
    </groups>
    <test name="Test" duration-ms="68817" started-at="2019-03-28T13:53:07Z" finished-at="2019-03-28T13:54:16Z">
      <class name="com.dx.testScripts.TestRegister">
        <test-method status="PASS" signature="SetUp()[pri:0, instance:com.dx.testScripts.TestRegister@48503868]" name="SetUp" is-config="true" duration-ms="17231" started-at="2019-03-28T21:53:07Z" finished-at="2019-03-28T21:53:24Z">
          <reporter-output>
          </reporter-output>
        </test-method> <!-- SetUp -->
        <test-method status="FAIL" signature="test_register_sucess()[pri:0, instance:com.dx.testScripts.TestRegister@48503868]" name="test_register_sucess" duration-ms="50379" started-at="2019-03-28T21:53:24Z" finished-at="2019-03-28T21:54:15Z">
          <exception class="java.lang.AssertionError">
            <message>
              <![CDATA[测试步骤有失败，整个测试用例执行失败]]>
            </message>
            <full-stacktrace>
              <![CDATA[java.lang.AssertionError: 测试步骤有失败，整个测试用例执行失败
	at org.testng.Assert.fail(Assert.java:94)
	at com.dx.testScripts.TestRegister.test_register_sucess(TestRegister.java:84)
	at sun.reflect.NativeMethodAccessorImpl.invoke0(Native Method)
	at sun.reflect.NativeMethodAccessorImpl.invoke(NativeMethodAccessorImpl.java:62)
	at sun.reflect.DelegatingMethodAccessorImpl.invoke(DelegatingMethodAccessorImpl.java:43)
	at java.lang.reflect.Method.invoke(Method.java:498)
	at org.testng.internal.MethodInvocationHelper.invokeMethod(MethodInvocationHelper.java:85)
	at org.testng.internal.Invoker.invokeMethod(Invoker.java:639)
	at org.testng.internal.Invoker.invokeTestMethod(Invoker.java:816)
	at org.testng.internal.Invoker.invokeTestMethods(Invoker.java:1124)
	at org.testng.internal.TestMethodWorker.invokeTestMethods(TestMethodWorker.java:125)
	at org.testng.internal.TestMethodWorker.run(TestMethodWorker.java:108)
	at org.testng.TestRunner.privateRun(TestRunner.java:774)
	at org.testng.TestRunner.run(TestRunner.java:624)
	at org.testng.SuiteRunner.runTest(SuiteRunner.java:359)
	at org.testng.SuiteRunner.runSequentially(SuiteRunner.java:354)
	at org.testng.SuiteRunner.privateRun(SuiteRunner.java:312)
	at org.testng.SuiteRunner.run(SuiteRunner.java:261)
	at org.testng.SuiteRunnerWorker.runSuite(SuiteRunnerWorker.java:52)
	at org.testng.SuiteRunnerWorker.run(SuiteRunnerWorker.java:86)
	at org.testng.TestNG.runSuitesSequentially(TestNG.java:1215)
	at org.testng.TestNG.runSuitesLocally(TestNG.java:1140)
	at org.testng.TestNG.run(TestNG.java:1048)
	at org.apache.maven.surefire.testng.TestNGExecutor.run(TestNGExecutor.java:283)
	at org.apache.maven.surefire.testng.TestNGXmlTestSuite.execute(TestNGXmlTestSuite.java:75)
	at org.apache.maven.surefire.testng.TestNGProvider.invoke(TestNGProvider.java:120)
	at org.apache.maven.surefire.booter.ForkedBooter.invokeProviderInSameClassLoader(ForkedBooter.java:386)
	at org.apache.maven.surefire.booter.ForkedBooter.runSuitesInProcess(ForkedBooter.java:323)
	at org.apache.maven.surefire.booter.ForkedBooter.main(ForkedBooter.java:143)
]]>
            </full-stacktrace>
          </exception> <!-- java.lang.AssertionError -->
          <reporter-output>
          </reporter-output>
        </test-method> <!-- test_register_sucess -->
        <test-method status="PASS" signature="endTest()[pri:0, instance:com.dx.testScripts.TestRegister@48503868]" name="endTest" is-config="true" duration-ms="1179" started-at="2019-03-28T21:54:15Z" finished-at="2019-03-28T21:54:16Z">
          <reporter-output>
          </reporter-output>
        </test-method> <!-- endTest -->
      </class> <!-- com.dx.testScripts.TestRegister -->
    </test> <!-- Test -->
  </suite> <!-- Suite -->
</testng-results>
